<?xml version="1.0" ?>
<robot name="robot">
  <material name="black">
    <color rgba="0.0 0.0 0.0 1.0"/>
  </material>
  <material name="blue">
    <color rgba="0.0 0.0 0.8 1.0"/>
  </material>
  <material name="green">
    <color rgba="0.0 0.8 0.0 1.0"/>
  </material>
  <material name="grey">
    <color rgba="0.2 0.2 0.2 1.0"/>
  </material>
  <material name="silver">
    <color rgba="0.9137254901960784 0.9137254901960784 0.8470588235294118 1.0"/>
  </material>
  <material name="orange">
    <color rgba="1.0 0.4235294117647059 0.0392156862745098 1.0"/>
  </material>
  <material name="brown">
    <color rgba="0.8705882352941177 0.8117647058823529 0.7647058823529411 1.0"/>
  </material>
  <material name="red">
    <color rgba="0.8 0.0 0.0 1.0"/>
  </material>
  <material name="white">
    <color rgba="1.0 1.0 1.0 1.0"/>
  </material>
  <link name="base">
    <visual>
      <origin rpy="0 0 0" xyz="0 0 0"/>
      <geometry>
        <mesh filename="../meshes/trunk.dae" scale="1 1 1"/>
      </geometry>
    </visual>
    <collision>
      <origin rpy="0 0 0" xyz="0 0 0"/>
      <geometry>
        <box size="0.99 0.34 0.24"/>
      </geometry>
    </collision>
    <inertial>
      <origin rpy="0 0 0" xyz="0.0014923112 -0.0014397771 -0.0094584260"/>
      <mass value="41.377848"/>
      <inertia ixx="0.47630359" ixy="-3.9611174E-03" ixz="0.020116265" iyy="1.8915135" iyz="-4.4176612E-03" izz="2.1035448"/>
    </inertial>
  </link>
  
  <!-- Imu is fixed to the base link -->
  <joint name="imu_joint" type="fixed">
    <origin rpy="0. 0. 0." xyz="0. 0. 0."/>
    <parent link="base"/>
    <child link="imu"/>
  </joint>
  <!-- Imu link -->
  <link name="imu">
    <inertial>
      <mass value="0.1"/>
      <origin rpy="0 0 0" xyz="0 0 0"/>
      <inertia ixx="0.000001" ixy="0" ixz="0" iyy="0.000001" iyz="0" izz="0.000001"/>
    </inertial>
    <visual>
      <origin rpy="0 0 0" xyz="0 0 0"/>
      <geometry>
        <box size="0.015 0.015 0.004"/>
      </geometry>
    </visual>
    <material name="orange">
      <color rgba="255 108 10 255"/>
    </material>
  </link>
  <gazebo reference="imu">
    <material>Gazebo/Orange</material>
  </gazebo>
  <gazebo reference="imu_joint">
    <disableFixedJointLumping>true</disableFixedJointLumping>
  </gazebo>
  
  <link
    name="arm_link0">
    <inertial>
      <origin
        xyz="1.04193988601165E-17 -2.06800069864048E-18 0.0306919872517665"
        rpy="0 0 0" />
      <mass
        value="0.154950873811881" />
      <inertia
        ixx="7.6280725825903E-05"
        ixy="-2.8331857255032E-21"
        ixz="-9.60864892161926E-21"
        iyy="7.5743677536133E-05"
        iyz="-7.23203741807483E-21"
        izz="6.94178921980713E-05" />
    </inertial>
    <visual>
      <origin
        xyz="0 0 0"
        rpy="0 0 0" />
      <geometry>
        <mesh
          filename="../meshes/link0.dae" />
      </geometry>
      <material
        name="">
        <color
          rgba="0.752941176470588 0.752941176470588 0.752941176470588 1" />
      </material>
    </visual>
  </link>
  <joint
    name="joint0"
    type="fixed">
    <origin
      xyz="0.332 0. 0.105"
      rpy="0 0 1.57" />
    <parent
      link="base" />
    <child
      link="arm_link0" />
  </joint>
  <link
    name="arm_link1">
    <inertial>
      <origin
        xyz="-0.00243668436201439 -0.006191415441136 0.0184110269010454"
        rpy="0 0 0" />
      <mass
        value="0.0465087787338035" />
      <inertia
        ixx="1.38543050772712E-05"
        ixy="1.14690917508463E-07"
        ixz="-1.53505123825081E-07"
        iyy="1.40483464923309E-05"
        iyz="3.12756534836822E-06"
        izz="1.49283119185331E-05" />
    </inertial>
    <visual>
      <origin
        xyz="0 0 0"
        rpy="0 0 0" />
      <geometry>
        <mesh
          filename="../meshes/link1.dae" />
      </geometry>
      <material
        name="">
        <color
          rgba="0.752941176470588 0.752941176470588 0.752941176470588 1" />
      </material>
    </visual>
  </link>
  <joint
    name="arm_joint1"
    type="revolute">
    <origin
      xyz="0 0 0.0605000000000002"
      rpy="0 0 0" />
    <parent
      link="arm_link0" />
    <child
      link="arm_link1" />
    <axis
      xyz="0 0 1" />
    <limit
      lower="-3.14"
      upper="3.14"
      effort="100"
      velocity="100" />
  </joint>
  <link
    name="arm_link2">
    <inertial>
      <origin
        xyz="0.132663920183335 0.000103506259278768 -0.0010415189341013"
        rpy="0 0 0" />
      <mass
        value="0.822766943132133" />
      <inertia
        ixx="0.000269943143027721"
        ixy="-2.15689204151916E-05"
        ixz="-1.40510780649704E-07"
        iyy="0.00274078506399191"
        iyz="-3.25705162840667E-08"
        izz="0.00281320873116607" />
    </inertial>
    <visual>
      <origin
        xyz="0 0 0"
        rpy="0 0 0" />
      <geometry>
        <mesh
          filename="../meshes/link2.dae" />
      </geometry>
      <material
        name="">
        <color
          rgba="0.752941176470588 0.752941176470588 0.752941176470588 1" />
      </material>
    </visual>
  </link>
  <joint
    name="arm_joint2"
    type="revolute">
    <origin
      xyz="0.000749999999995356 -0.0200000000000009 0.0399999999999998"
      rpy="1.5707963267949 0 1.5707963267949" />
    <parent
      link="arm_link1" />
    <child
      link="arm_link2" />
    <axis
      xyz="0 0 -1" />
    <limit
      lower="-3.6"
      upper="0.28"
      effort="100"
      velocity="100" />
  </joint>
  <link
    name="arm_link3">
    <inertial>
      <origin
        xyz="0.14108 -0.053069 -0.0012758"
        rpy="0 0 0" />
      <mass
        value="0.451084119008658" />
      <inertia
        ixx="0.000146463690877388"
        ixy="0.000108278431799258"
        ixz="-1.14918312139153E-05"
        iyy="0.00137487396946499"
        iyz="5.3153018327198E-06"
        izz="0.0014340770881379" />
    </inertial>
    <visual>
      <origin
        xyz="0 0 0"
        rpy="0 0 0" />
      <geometry>
        <mesh
          filename="../meshes/link3.dae" />
      </geometry>
      <material
        name="">
        <color
          rgba="0.752941176470588 0.752941176470588 0.752941176470588 1" />
      </material>
    </visual>
  </link>
  <joint
    name="arm_joint3"
    type="revolute">
    <origin
      xyz="0.264 0 0"
      rpy="0 0 3.1416" />
    <parent
      link="arm_link2" />
    <child
      link="arm_link3" />
    <axis
      xyz="0 0 -1" />
    <limit
      lower="0"
      upper="3.14"
      effort="100"
      velocity="100" />
  </joint>
  <link
    name="arm_link4">
    <inertial>
      <origin
        xyz="0.033502 -0.027529 -0.0063895"
        rpy="0 0 0" />
      <mass
        value="0.042855" />
      <inertia
        ixx="2.3925E-05"
        ixy="3.4346E-06"
        ixz="-4.2531E-06"
        iyy="2.5668E-05"
        iyz="2.1761E-06"
        izz="2.4119E-05" />
    </inertial>
    <visual>
      <origin
        xyz="0 0 0"
        rpy="0 0 0" />
      <geometry>
        <mesh
          filename="../meshes/link4.dae" />
      </geometry>
      <material
        name="">
        <color
          rgba="1 1 1 1" />
      </material>
    </visual>
  </link>
  <joint
    name="arm_joint4"
    type="revolute">
    <origin
      xyz="0.245 -0.056 -0.000475"
      rpy="0 0 0" />
    <parent
      link="arm_link3" />
    <child
      link="arm_link4" />
    <axis
      xyz="0 0 -1" />
    <limit
      lower="-1.571"
      upper="1.571"
      effort="100"
      velocity="100" />
  </joint>
  <link
    name="arm_link5">
    <inertial>
      <origin
        xyz="7.39496806869756E-05 0.00390756676405528 -0.0521915532008786"
        rpy="0 0 0" />
      <mass
        value="0.208851517655746" />
      <inertia
        ixx="6.88759462513615E-05"
        ixy="1.74076185008027E-07"
        ixz="9.47036416876195E-09"
        iyy="7.82640881069056E-05"
        iyz="-8.13674688946157E-07"
        izz="7.80502525587007E-05" />
    </inertial>
    <visual>
      <origin
        xyz="0 0 0"
        rpy="0 0 0" />
      <geometry>
        <mesh
          filename="../meshes/link5.dae" />
      </geometry>
      <material
        name="">
        <color
          rgba="0.752941176470588 0.752941176470588 0.752941176470588 1" />
      </material>
    </visual>
  </link>
  <joint
    name="arm_joint5"
    type="revolute">
    <origin
      xyz="0.06675 -0.084 -0.000275"
      rpy="1.5708 1.5708 0" />
    <parent
      link="arm_link4" />
    <child
      link="arm_link5" />
    <axis
      xyz="0 0 1" />
    <limit
      lower="-1.571"
      upper="1.571"
      effort="100"
      velocity="100" />
  </joint>
  <link
    name="arm_link6">
    <inertial>
      <origin
        xyz="0.00049313 9.848E-05 0.031695"
        rpy="0 0 0" />
      <mass
        value="0.123916977852968" />
      <inertia
        ixx="2.50413167035512E-05"
        ixy="9.83170018920875E-07"
        ixz="1.40401305267416E-06"
        iyy="0.000101574358657965"
        iyz="-1.83024792957642E-08"
        izz="0.000113465016821662" />
    </inertial>
    <visual>
      <origin
        xyz="0 0 0"
        rpy="0 0 0" />
      <geometry>
        <mesh
          filename="../meshes/link6.dae" />
      </geometry>
      <material
        name="">
        <color
          rgba="1 1 1 1" />
      </material>
    </visual>
  </link>
  <joint
    name="arm_joint6"
    type="revolute">
    <origin
      xyz="0.00046414 0.028539 -0.082947"
      rpy="-1.5708 0 0" />
    <parent
      link="arm_link5" />
    <child
      link="arm_link6" />
    <axis
      xyz="-0.015856 0 -0.99987" />
    <limit
      lower="-3.14"
      upper="3.14"
      effort="100"
      velocity="100" />
  </joint>
  <link
    name="gripper1">
    <inertial>
      <origin
        xyz="-0.010949 -0.007984 -0.0053619"
        rpy="0 0 0" />
      <mass
        value="0.027146" />
      <inertia
        ixx="8.9441E-06"
        ixy="6.8743E-07"
        ixz="-3.1012E-06"
        iyy="1.1334E-05"
        iyz="1.6273E-07"
        izz="1.5094E-05" />
    </inertial>
    <visual>
      <origin
        xyz="0 0 0"
        rpy="0 0 0" />
      <geometry>
        <mesh
          filename="../meshes/gripper1.dae" />
      </geometry>
      <material
        name="">
        <color
          rgba="1 1 1 1" />
      </material>
    </visual>
  </link>
  <joint
    name="arm_joint7"
    type="prismatic">
    <origin
      xyz="-0.0218441952806044 -0.00464472233071411 0.070282758534191"
      rpy="0.00229467780858847 1.55494011731642 -3.14159265358975" />
    <parent
      link="arm_link6" />
    <child
      link="gripper1" />
    <axis
      xyz="0 0 1" />
    <limit
      lower="0"
      upper="0.04764"
      effort="100"
      velocity="10" />
  </joint>
  <link
    name="gripper2">
    <inertial>
      <origin
        xyz="-0.011249 0.0029863 -0.0053619"
        rpy="0 0 0" />
      <mass
        value="0.027146" />
      <inertia
        ixx="9.1856E-06"
        ixy="1.6166E-06"
        ixz="-3.1012E-06"
        iyy="1.1334E-05"
        iyz="6.1248E-07"
        izz="1.5336E-05" />
    </inertial>
    <visual>
      <origin
        xyz="0 0 0"
        rpy="0 0 0" />
      <geometry>
        <mesh
          filename="../meshes/gripper2.dae" />
      </geometry>
      <material
        name="">
        <color
          rgba="1 1 1 1" />
      </material>
    </visual>
  </link>
  <joint
    name="arm_joint8"
    type="prismatic">
    <origin
      xyz="0.0240124026414632 -0.00444997198895219 0.0692555480519135"
      rpy="-3.1392979757812 1.55494011731642 -3.14159265358975" />
    <parent
      link="arm_link6" />
    <child
      link="gripper2" />
    <axis
      xyz="0 0 -1" />
    <limit
      lower="-0.04764"
      upper="0"
      effort="100"
      velocity="10" />
  </joint>

  <joint name="FR_hip_joint" type="revolute">
    <origin rpy="0 0 0" xyz="0.325 -0.1125 0"/>
    <parent link="base"/>
    <child link="FR_hip"/>
    <axis xyz="1 0 0"/>
    <dynamics damping="0" friction="0"/>
    <limit effort="160" lower="-0.87" upper="0.69" velocity="19.3"/>
  </joint>
  <link name="FR_hip">
    <visual>
      <origin rpy="3.141592653589793 0 0" xyz="0 0 0"/>
      <geometry>
        <mesh filename="../meshes/hip.dae" scale="1 1 1"/>
      </geometry>
      <material name="orange"/>
    </visual>
    <inertial>
      <origin rpy="0 0 0" xyz="-0.0011794 0.02693 -5.8859E-07"/>
      <mass value="2.7264"/>
      <inertia ixx="0.0043529" ixy="7.7592E-06" ixz="-9.9737E-09" iyy="0.0056391" iyz="1.7393E-08" izz="0.0047569"/>
    </inertial>
  </link>
  <joint name="FR_thigh_joint" type="revolute">
    <origin rpy="0 0 0" xyz="0 -0.126375 0"/>
    <parent link="FR_hip"/>
    <child link="FR_thigh"/>
    <axis xyz="0 1 0"/>
    <dynamics damping="0" friction="0"/>
    <limit effort="180" lower="-1.78" upper="3.40" velocity="21.6"/>
  </joint>
  <link name="FR_thigh">
    <visual>
      <origin rpy="0 0 0" xyz="0 0 0"/>
      <geometry>
        <mesh filename="../meshes/thigh_mirror.dae" scale="1 1 1"/>
      </geometry>
      <material name="orange"/>
    </visual>
    <inertial>
      <origin rpy="0 0 0" xyz="0.008023 0.0407086 -0.0477057"/>
      <mass value="4.5843711"/>
      <inertia ixx="0.0568903" ixy="-1.3859024E-03" ixz="-0.0040888" iyy="0.055707534" iyz="-0.0090795" izz="0.0119193"/>
    </inertial>
  </link>
  <joint name="FR_calf_joint" type="revolute">
    <origin rpy="0 0 0" xyz="0 0 -0.34"/>
    <parent link="FR_thigh"/>
    <child link="FR_calf"/>
    <axis xyz="0 1 0"/>
    <dynamics damping="0" friction="0"/>
    <limit effort="452" lower="-2.53" upper="-0.45" velocity="18.8"/>
  </joint>
  <link name="FR_calf">
    <visual>
      <origin rpy="0 0 0" xyz="0 0 0"/>
      <geometry>
        <mesh filename="../meshes/calf.dae" scale="1 1 1"/>
      </geometry>
      <material name="orange"/>
    </visual>
    <collision>
      <origin rpy="0 1.5707963267948966 0" xyz="0.0 0 -0.17"/>
      <geometry>
        <box size="0.25 0.04 0.0495"/>
      </geometry>
    </collision>
    <inertial>
      <origin rpy="0 0 0" xyz="-4.1136934E-03 -2.2641006E-06 -0.18227639"/>
      <mass value="0.82150729"/>
      <inertia ixx="0.017546212" ixy="-2.5076089E-09" ixz="-3.8977294E-05" iyy="0.017775449" iyz="-3.0610477E-07" izz="4.2961251E-04"/>
    </inertial>
  </link>
  <joint name="FR_foot_fixed" type="fixed" dont_collapse="true">
    <origin rpy="0 0 0" xyz="0 0 -0.34"/>
    <parent link="FR_calf"/>
    <child link="FR_FOOT"/>
  </joint>
  <link name="FR_FOOT">
    <collision>
      <origin rpy="0 0 0" xyz="0 0 0"/>
      <geometry>
        <sphere radius="0.045"/>
      </geometry>
    </collision>
    <inertial>
      <mass value="0.12"/>
      <inertia ixx="1.000e-09" ixy="0.0" ixz="0.0" iyy="1.000e-09" iyz="0.0" izz="1.000e-09"/>
    </inertial>
  </link>
  <joint name="FL_hip_joint" type="revolute">
    <origin rpy="0 0 0" xyz="0.325 0.1125 0"/>
    <parent link="base"/>
    <child link="FL_hip"/>
    <axis xyz="1 0 0"/>
    <dynamics damping="0" friction="0"/>
    <limit effort="160" lower="-0.69" upper="0.87" velocity="19.3"/>
  </joint>
  <link name="FL_hip">
    <visual>
      <origin rpy="0 0 0" xyz="0 0 0"/>
      <geometry>
        <mesh filename="../meshes/hip.dae" scale="1 1 1"/>
      </geometry>
      <material name="orange"/>
    </visual>
    <inertial>
      <origin rpy="0 0 0" xyz="-0.0011794 -0.02693 5.8859E-07"/>
      <mass value="2.7264"/>
      <inertia ixx="0.0043529" ixy="-7.7592E-06" ixz="9.9737E-09" iyy="0.0056391" iyz="1.7393E-08" izz="0.0047569"/>
    </inertial>
  </link>
  <joint name="FL_thigh_joint" type="revolute">
    <origin rpy="0 0 0" xyz="0 0.126375 0"/>
    <parent link="FL_hip"/>
    <child link="FL_thigh"/>
    <axis xyz="0 1 0"/>
    <dynamics damping="0" friction="0"/>
    <limit effort="180" lower="-1.78" upper="3.40" velocity="21.6"/>
  </joint>
  <link name="FL_thigh">
    <visual>
      <origin rpy="0 0 0" xyz="0 0 0"/>
      <geometry>
        <mesh filename="../meshes/thigh.dae" scale="1 1 1"/>
      </geometry>
      <material name="orange"/>
    </visual>
    <inertial>
      <origin rpy="0 0 0" xyz="0.008023 -0.0407086 -0.0477057"/>
      <mass value="4.5843711"/>
      <inertia ixx="0.0568903" ixy="1.3859024E-03" ixz="-0.0040888" iyy="0.055707534" iyz="0.0090795" izz="0.0119193"/>
    </inertial>
  </link>
  <joint name="FL_calf_joint" type="revolute">
    <origin rpy="0 0 0" xyz="0 0 -0.34"/>
    <parent link="FL_thigh"/>
    <child link="FL_calf"/>
    <axis xyz="0 1 0"/>
    <dynamics damping="0" friction="0"/>
    <limit effort="452" lower="-2.53" upper="-0.45" velocity="18.8"/>
  </joint>
  <link name="FL_calf">
    <visual>
      <origin rpy="0 0 0" xyz="0 0 0"/>
      <geometry>
        <mesh filename="../meshes/calf.dae" scale="1 1 1"/>
      </geometry>
      <material name="orange"/>
    </visual>
    <collision>
      <origin rpy="0 1.5707963267948966 0" xyz="0.0 0 -0.17"/>
      <geometry>
        <box size="0.25 0.04 0.0495"/>
      </geometry>
    </collision>
    <inertial>
      <origin rpy="0 0 0" xyz="-4.1136934E-03 2.2641006E-06 -0.18227639"/>
      <mass value="0.82150729"/>
      <inertia ixx="0.017546212" ixy="-2.5076089E-09" ixz="3.8977294E-05" iyy="0.017775449" iyz="3.0610477E-07" izz="4.2961251E-04"/>
    </inertial>
  </link>
  <joint name="FL_foot_fixed" type="fixed" dont_collapse="true">
    <origin rpy="0 0 0" xyz="0 0 -0.34"/>
    <parent link="FL_calf"/>
    <child link="FL_FOOT"/>
  </joint>
  <link name="FL_FOOT">
    <collision>
      <origin rpy="0 0 0" xyz="0 0 0"/>
      <geometry>
        <sphere radius="0.045"/>
      </geometry>
    </collision>
    <inertial>
      <mass value="0.12"/>
      <inertia ixx="1.000e-09" ixy="0.0" ixz="0.0" iyy="1.000e-09" iyz="0.0" izz="1.000e-09"/>
    </inertial>
  </link>
  <joint name="RR_hip_joint" type="revolute">
    <origin rpy="0 0 0" xyz="-0.325 -0.1125 0"/>
    <parent link="base"/>
    <child link="RR_hip"/>
    <axis xyz="1 0 0"/>
    <dynamics damping="0" friction="0"/>
    <limit effort="160" lower="-0.87" upper="0.69" velocity="19.3"/>
  </joint>
  <link name="RR_hip">
    <visual>
      <origin rpy="3.141592653589793 3.141592653589793 0" xyz="0 0 0"/>
      <geometry>
        <mesh filename="../meshes/hip.dae" scale="1 1 1"/>
      </geometry>
      <material name="orange"/>
    </visual>
    <inertial>
      <origin rpy="0 0 0" xyz="0.0011794 0.02693 5.8859E-07"/>
      <mass value="2.7264"/>
      <inertia ixx="0.0043529" ixy="-7.7592E-06" ixz="-9.9737E-09" iyy="0.0056391" iyz="-1.7393E-08" izz="0.0047569"/>
    </inertial>
  </link>
  <joint name="RR_thigh_joint" type="revolute">
    <origin rpy="0 0 0" xyz="0 -0.126375 0"/>
    <parent link="RR_hip"/>
    <child link="RR_thigh"/>
    <axis xyz="0 1 0"/>
    <dynamics damping="0" friction="0"/>
    <limit effort="180" lower="-1.30" upper="4.00" velocity="21.6"/>
  </joint>
  <link name="RR_thigh">
    <visual>
      <origin rpy="0 0 0" xyz="0 0 0"/>
      <geometry>
        <mesh filename="../meshes/thigh_mirror.dae" scale="1 1 1"/>
      </geometry>
      <material name="orange"/>
    </visual>
    <inertial>
      <origin rpy="0 0 0" xyz="0.008023 0.0407086 -0.0477057"/>
      <mass value="4.5843711"/>
      <inertia ixx="0.0568903" ixy="-1.3859024E-03" ixz="-0.0040888" iyy="0.055707534" iyz="-0.0090795" izz="0.0119193"/>
    </inertial>
  </link>
  <joint name="RR_calf_joint" type="revolute">
    <origin rpy="0 0 0" xyz="0 0 -0.34"/>
    <parent link="RR_thigh"/>
    <child link="RR_calf"/>
    <axis xyz="0 1 0"/>
    <dynamics damping="0" friction="0"/>
    <limit effort="452" lower="-2.53" upper="-0.45" velocity="18.8"/>
  </joint>
  <link name="RR_calf">
    <visual>
      <origin rpy="0 0 0" xyz="0 0 0"/>
      <geometry>
        <mesh filename="../meshes/calf.dae" scale="1 1 1"/>
      </geometry>
      <material name="orange"/>
    </visual>
    <collision>
      <origin rpy="0 1.5707963267948966 0" xyz="0.0 0 -0.17"/>
      <geometry>
        <box size="0.25 0.04 0.0495"/>
      </geometry>
    </collision>
    <inertial>
      <origin rpy="0 0 0" xyz="-4.1136934E-03 -2.2641006E-06 -0.18227639"/>
      <mass value="0.82150729"/>
      <inertia ixx="0.017546212" ixy="-2.5076089E-09" ixz="-3.8977294E-05" iyy="0.017775449" iyz="-3.0610477E-07" izz="4.2961251E-04"/>
    </inertial>
  </link>
  <joint name="RR_foot_fixed" type="fixed" dont_collapse="true">
    <origin rpy="0 0 0" xyz="0 0 -0.34"/>
    <parent link="RR_calf"/>
    <child link="RR_FOOT"/>
  </joint>
  <link name="RR_FOOT">
    <collision>
      <origin rpy="0 0 0" xyz="0 0 0"/>
      <geometry>
        <sphere radius="0.045"/>
      </geometry>
    </collision>
    <inertial>
      <mass value="0.12"/>
      <inertia ixx="1.000e-09" ixy="0.0" ixz="0.0" iyy="1.000e-09" iyz="0.0" izz="1.000e-09"/>
    </inertial>
  </link>
  <joint name="RL_hip_joint" type="revolute">
    <origin rpy="0 0 0" xyz="-0.325 0.1125 0"/>
    <parent link="base"/>
    <child link="RL_hip"/>
    <axis xyz="1 0 0"/>
    <dynamics damping="0" friction="0"/>
    <limit effort="160" lower="-0.69" upper="0.87" velocity="19.3"/>
  </joint>
  <link name="RL_hip">
    <visual>
      <origin rpy="0 3.141592653589793 0" xyz="0 0 0"/>
      <geometry>
        <mesh filename="../meshes/hip.dae" scale="1 1 1"/>
      </geometry>
      <material name="orange"/>
    </visual>
    <inertial>
      <origin rpy="0 0 0" xyz="0.0011794 -0.02693 -5.8859E-07"/>
      <mass value="2.7264"/>
      <inertia ixx="0.0043529" ixy="7.7592E-06" ixz="9.9737E-09" iyy="0.0056391" iyz="-1.7393E-08" izz="0.0047569"/>
    </inertial>
  </link>
  <joint name="RL_thigh_joint" type="revolute">
    <origin rpy="0 0 0" xyz="0 0.126375 0"/>
    <parent link="RL_hip"/>
    <child link="RL_thigh"/>
    <axis xyz="0 1 0"/>
    <dynamics damping="0" friction="0"/>
    <limit effort="180" lower="-1.30" upper="4.00" velocity="21.6"/>
  </joint>
  <link name="RL_thigh">
    <visual>
      <origin rpy="0 0 0" xyz="0 0 0"/>
      <geometry>
        <mesh filename="../meshes/thigh.dae" scale="1 1 1"/>
      </geometry>
      <material name="orange"/>
    </visual>
    <inertial>
      <origin rpy="0 0 0" xyz="0.008023 -0.0407086 -0.0477057"/>
      <mass value="4.5843711"/>
      <inertia ixx="0.0568903" ixy="1.3859024E-03" ixz="-0.0040888" iyy="0.055707534" iyz="0.0090795" izz="0.0119193"/>
    </inertial>
  </link>
  <joint name="RL_calf_joint" type="revolute">
    <origin rpy="0 0 0" xyz="0 0 -0.34"/>
    <parent link="RL_thigh"/>
    <child link="RL_calf"/>
    <axis xyz="0 1 0"/>
    <dynamics damping="0" friction="0"/>
    <limit effort="452" lower="-2.53" upper="-0.45" velocity="18.8"/>
  </joint>
  <link name="RL_calf">
    <visual>
      <origin rpy="0 0 0" xyz="0 0 0"/>
      <geometry>
        <mesh filename="../meshes/calf.dae" scale="1 1 1"/>
      </geometry>
      <material name="orange"/>
    </visual>
    <collision>
      <origin rpy="0 1.5707963267948966 0" xyz="0.0 0 -0.17"/>
      <geometry>
        <box size="0.25 0.04 0.0495"/>
      </geometry>
    </collision>
    <inertial>
      <origin rpy="0 0 0" xyz="-4.1136934E-03 2.2641006E-06 -0.18227639"/>
      <mass value="0.82150729"/>
      <inertia ixx="0.017546212" ixy="-2.5076089E-09" ixz="3.8977294E-05" iyy="0.017775449" iyz="3.0610477E-07" izz="4.2961251E-04"/>
    </inertial>
  </link>
  <joint name="RL_foot_fixed" type="fixed" dont_collapse="true">
    <origin rpy="0 0 0" xyz="0 0 -0.34"/>
    <parent link="RL_calf"/>
    <child link="RL_FOOT"/>
  </joint>
  <link name="RL_FOOT">
    <collision>
      <origin rpy="0 0 0" xyz="0 0 0"/>
      <geometry>
        <sphere radius="0.045"/>
      </geometry>
    </collision>
    <inertial>
      <mass value="0.12"/>
      <inertia ixx="1.000e-09" ixy="0.0" ixz="0.0" iyy="1.000e-09" iyz="0.0" izz="1.000e-09"/>
    </inertial>
  </link>
</robot>

